Workbook

Sheet blank
B4: Observe Date/Class
B5: 1 | C5: Lesson planning and preparation | D5: The teacher is following a clear and well-structured lesson plan. | E5: The teacher tailors the lesson to meet the students’ needs and proficiency level. | F5: Appropriate and varied materials are prepared and used effectively | G5: Average Observe | H5: Comments
G6: =AVERAGE(D6,E6,F6)
B7: 2 | C7: Classroom management | D7: The classroom environment is conductive to learning. | E7: Students are actively engaged and participating throughout the lesson. | F7: The teacher manages class time, transitions and activities effectively. | G7: Average Observe | H7: Comments:
G8: =AVERAGE(D8,E8,F8)
B9: 3 | C9: Instructional delivery | D9: The teacher provides clear and differentiated instructions and explanations. | E9: The teacher uses the appropriate language level for students. | F9: The teacher encourages interaction and communication among students. | G9: Average Observe | H9: Comments
G10: =AVERAGE(D10,E10,F10)
B11: 4 | C11: Assessment and feedback | D11: The teacher monitors student progress during the lesson. | E11: The teacher provides timely and constructive feedback. | F11: The teacher adjusts teaching based on students’ understanding and feedback | G11: Average Observe | H11: Comments
G12: =AVERAGE(D12,E12,F12)
B13: 5 | C13: Language use | D13: The teacher integrates grammar, vocabulary and pronunciation effectively. | E13: The teacher provides opportunities for students to practice and use English. | F13: The teacher is a proficient model of language. | G13: Average Observe | H13: Comments
G14: =AVERAGE(D14,E14,F14)
B15: Sum | D15: =SUM(D5:D14) | E15: =SUM(E5:E14) | F15: =SUM(F5:F14) | G15: =SUM(G5:G14)/5 | H15: =SUM(H5:H13)

Sheet Co Zero
B4: Observe Date/Class | H4: cvbvb
B5: 1 | C5: Lesson planning and preparation | D5: The teacher is following a clear and well-structured lesson plan. | E5: The teacher tailors the lesson to meet the students’ needs and proficiency level. | F5: Appropriate and varied materials are prepared and used effectively | G5: Average Observe | H5: Comments
G6: =AVERAGE(D6,E6,F6)
B7: 2 | C7: Classroom management | D7: The classroom environment is conductive to learning. | E7: Students are actively engaged and participating throughout the lesson. | F7: The teacher manages class time, transitions and activities effectively. | G7: Average Observe | H7: Comments:
G8: =AVERAGE(D8,E8,F8)
B9: 3 | C9: Instructional delivery | D9: The teacher provides clear and differentiated instructions and explanations. | E9: The teacher uses the appropriate language level for students. | F9: The teacher encourages interaction and communication among students. | G9: Average Observe | H9: Comments
G10: =AVERAGE(D10,E10,F10)
B11: 4 | C11: Assessment and feedback | D11: The teacher monitors student progress during the lesson. | E11: The teacher provides timely and constructive feedback. | F11: The teacher adjusts teaching based on students’ understanding and feedback | G11: Average Observe | H11: Comments
G12: =AVERAGE(D12,E12,F12)
B13: 5 | C13: Language use | D13: The teacher integrates grammar, vocabulary and pronunciation effectively. | E13: The teacher provides opportunities for students to practice and use English. | F13: The teacher is a proficient model of language. | G13: Average Observe | H13: Comments
G14: =AVERAGE(D14,E14,F14)
B15: Sum | D15: =SUM(D5:D14) | E15: =SUM(E5:E14) | F15: =SUM(F5:F14) | G15: =SUM(G5:G14)/5 | H15: =SUM(H5:H13)

Sheet co 1
B4: Observe Date/Class
B5: 1 | C5: Lesson planning and preparation | D5: The teacher is following a clear and well-structured lesson plan. | E5: The teacher tailors the lesson to meet the students’ needs and proficiency level. | F5: Appropriate and varied materials are prepared and used effectively | G5: Average Observe | H5: Comments
G6: =AVERAGE(D6,E6,F6)
B7: 2 | C7: Classroom management | D7: The classroom environment is conductive to learning. | E7: Students are actively engaged and participating throughout the lesson. | F7: The teacher manages class time, transitions and activities effectively. | G7: Average Observe | H7: Comments:
G8: =AVERAGE(D8,E8,F8)
B9: 3 | C9: Instructional delivery | D9: The teacher provides clear and differentiated instructions and explanations. | E9: The teacher uses the appropriate language level for students. | F9: The teacher encourages interaction and communication among students. | G9: Average Observe | H9: Comments
G10: =AVERAGE(D10,E10,F10)
B11: 4 | C11: Assessment and feedback | D11: The teacher monitors student progress during the lesson. | E11: The teacher provides timely and constructive feedback. | F11: The teacher adjusts teaching based on students’ understanding and feedback | G11: Average Observe | H11: Comments
G12: =AVERAGE(D12,E12,F12)
B13: 5 | C13: Language use | D13: The teacher integrates grammar, vocabulary and pronunciation effectively. | E13: The teacher provides opportunities for students to practice and use English. | F13: The teacher is a proficient model of language. | G13: Average Observe | H13: Comments
G14: =AVERAGE(D14,E14,F14)
B15: Sum | D15: =SUM(D5:D14) | E15: =SUM(E5:E14) | F15: =SUM(F5:F14) | G15: =SUM(G5:G14)/5 | H15: =SUM(H5:H13)

Sheet Co2
B4: Observe Date/Class
B5: 1 | C5: Lesson planning and preparation | D5: The teacher is following a clear and well-structured lesson plan. | E5: The teacher tailors the lesson to meet the students’ needs and proficiency level. | F5: Appropriate and varied materials are prepared and used effectively | G5: Average Observe | H5: Comments
G6: =AVERAGE(D6,E6,F6)
B7: 2 | C7: Classroom management | D7: The classroom environment is conductive to learning. | E7: Students are actively engaged and participating throughout the lesson. | F7: The teacher manages class time, transitions and activities effectively. | G7: Average Observe | H7: Comments:
G8: =AVERAGE(D8,E8,F8)
B9: 3 | C9: Instructional delivery | D9: The teacher provides clear and differentiated instructions and explanations. | E9: The teacher uses the appropriate language level for students. | F9: The teacher encourages interaction and communication among students. | G9: Average Observe | H9: Comments
G10: =AVERAGE(D10,E10,F10)
B11: 4 | C11: Assessment and feedback | D11: The teacher monitors student progress during the lesson. | E11: The teacher provides timely and constructive feedback. | F11: The teacher adjusts teaching based on students’ understanding and feedback | G11: Average Observe | H11: Comments
G12: =AVERAGE(D12,E12,F12)
B13: 5 | C13: Language use | D13: The teacher integrates grammar, vocabulary and pronunciation effectively. | E13: The teacher provides opportunities for students to practice and use English. | F13: The teacher is a proficient model of language. | G13: Average Observe | H13: Comments
G14: =AVERAGE(D14,E14,F14)
B15: Sum | D15: =SUM(D5:D14) | E15: =SUM(E5:E14) | F15: =SUM(F5:F14) | G15: =SUM(G5:G14)/5 | H15: =SUM(H5:H13)

Sheet Co3
B4: Observe Date/Class
B5: 1 | C5: Lesson planning and preparation | D5: The teacher is following a clear and well-structured lesson plan. | E5: The teacher tailors the lesson to meet the students’ needs and proficiency level. | F5: Appropriate and varied materials are prepared and used effectively | G5: Average Observe | H5: Comments
G6: =AVERAGE(D6,E6,F6)
B7: 2 | C7: Classroom management | D7: The classroom environment is conductive to learning. | E7: Students are actively engaged and participating throughout the lesson. | F7: The teacher manages class time, transitions and activities effectively. | G7: Average Observe | H7: Comments:
G8: =AVERAGE(D8,E8,F8)
B9: 3 | C9: Instructional delivery | D9: The teacher provides clear and differentiated instructions and explanations. | E9: The teacher uses the appropriate language level for students. | F9: The teacher encourages interaction and communication among students. | G9: Average Observe | H9: Comments
G10: =AVERAGE(D10,E10,F10)
B11: 4 | C11: Assessment and feedback | D11: The teacher monitors student progress during the lesson. | E11: The teacher provides timely and constructive feedback. | F11: The teacher adjusts teaching based on students’ understanding and feedback | G11: Average Observe | H11: Comments
G12: =AVERAGE(D12,E12,F12)
B13: 5 | C13: Language use | D13: The teacher integrates grammar, vocabulary and pronunciation effectively. | E13: The teacher provides opportunities for students to practice and use English. | F13: The teacher is a proficient model of language. | G13: Average Observe | H13: Comments
G14: =AVERAGE(D14,E14,F14)
B15: Sum | D15: =SUM(D5:D14) | E15: =SUM(E5:E14) | F15: =SUM(F5:F14) | G15: =SUM(G5:G14)/5 | H15: =SUM(H5:H13)

Sheet Co4
B4: Observe Date/Class
B5: 1 | C5: Lesson planning and preparation | D5: The teacher is following a clear and well-structured lesson plan. | E5: The teacher tailors the lesson to meet the students’ needs and proficiency level. | F5: Appropriate and varied materials are prepared and used effectively | G5: Average Observe | H5: Comments
G6: =AVERAGE(D6,E6,F6)
B7: 2 | C7: Classroom management | D7: The classroom environment is conductive to learning. | E7: Students are actively engaged and participating throughout the lesson. | F7: The teacher manages class time, transitions and activities effectively. | G7: Average Observe | H7: Comments:
G8: =AVERAGE(D8,E8,F8)
B9: 3 | C9: Instructional delivery | D9: The teacher provides clear and differentiated instructions and explanations. | E9: The teacher uses the appropriate language level for students. | F9: The teacher encourages interaction and communication among students. | G9: Average Observe | H9: Comments
G10: =AVERAGE(D10,E10,F10)
B11: 4 | C11: Assessment and feedback | D11: The teacher monitors student progress during the lesson. | E11: The teacher provides timely and constructive feedback. | F11: The teacher adjusts teaching based on students’ understanding and feedback | G11: Average Observe | H11: Comments
G12: =AVERAGE(D12,E12,F12)
B13: 5 | C13: Language use | D13: The teacher integrates grammar, vocabulary and pronunciation effectively. | E13: The teacher provides opportunities for students to practice and use English. | F13: The teacher is a proficient model of language. | G13: Average Observe | H13: Comments
G14: =AVERAGE(D14,E14,F14)
B15: Sum | D15: =SUM(D5:D14) | E15: =SUM(E5:E14) | F15: =SUM(F5:F14) | G15: =SUM(G5:G14)/5 | H15: =SUM(H5:H13)

Sheet Co5
B4: Observe Date/Class
B5: 1 | C5: Lesson planning and preparation | D5: The teacher is following a clear and well-structured lesson plan. | E5: The teacher tailors the lesson to meet the students’ needs and proficiency level. | F5: Appropriate and varied materials are prepared and used effectively | G5: Average Observe | H5: Comments
G6: =AVERAGE(D6,E6,F6)
B7: 2 | C7: Classroom management | D7: The classroom environment is conductive to learning. | E7: Students are actively engaged and participating throughout the lesson. | F7: The teacher manages class time, transitions and activities effectively. | G7: Average Observe | H7: Comments:
G8: =AVERAGE(D8,E8,F8)
B9: 3 | C9: Instructional delivery | D9: The teacher provides clear and differentiated instructions and explanations. | E9: The teacher uses the appropriate language level for students. | F9: The teacher encourages interaction and communication among students. | G9: Average Observe | H9: Comments
G10: =AVERAGE(D10,E10,F10)
B11: 4 | C11: Assessment and feedback | D11: The teacher monitors student progress during the lesson. | E11: The teacher provides timely and constructive feedback. | F11: The teacher adjusts teaching based on students’ understanding and feedback | G11: Average Observe | H11: Comments
G12: =AVERAGE(D12,E12,F12)
B13: 5 | C13: Language use | D13: The teacher integrates grammar, vocabulary and pronunciation effectively. | E13: The teacher provides opportunities for students to practice and use English. | F13: The teacher is a proficient model of language. | G13: Average Observe | H13: Comments
G14: =AVERAGE(D14,E14,F14)
B15: Sum | D15: =SUM(D5:D14) | E15: =SUM(E5:E14) | F15: =SUM(F5:F14) | G15: =SUM(G5:G14)/5 | H15: =SUM(H5:H13)

Sheet Co6
B4: Observe Date/Class
B5: 1 | C5: Lesson planning and preparation | D5: The teacher is following a clear and well-structured lesson plan. | E5: The teacher tailors the lesson to meet the students’ needs and proficiency level. | F5: Appropriate and varied materials are prepared and used effectively | G5: Average Observe | H5: Comments
G6: =AVERAGE(D6,E6,F6)
B7: 2 | C7: Classroom management | D7: The classroom environment is conductive to learning. | E7: Students are actively engaged and participating throughout the lesson. | F7: The teacher manages class time, transitions and activities effectively. | G7: Average Observe | H7: Comments:
G8: =AVERAGE(D8,E8,F8)
B9: 3 | C9: Instructional delivery | D9: The teacher provides clear and differentiated instructions and explanations. | E9: The teacher uses the appropriate language level for students. | F9: The teacher encourages interaction and communication among students. | G9: Average Observe | H9: Comments
G10: =AVERAGE(D10,E10,F10)
B11: 4 | C11: Assessment and feedback | D11: The teacher monitors student progress during the lesson. | E11: The teacher provides timely and constructive feedback. | F11: The teacher adjusts teaching based on students’ understanding and feedback | G11: Average Observe | H11: Comments
G12: =AVERAGE(D12,E12,F12)
B13: 5 | C13: Language use | D13: The teacher integrates grammar, vocabulary and pronunciation effectively. | E13: The teacher provides opportunities for students to practice and use English. | F13: The teacher is a proficient model of language. | G13: Average Observe | H13: Comments
G14: =AVERAGE(D14,E14,F14)
B15: Sum | D15: =SUM(D5:D14) | E15: =SUM(E5:E14) | F15: =SUM(F5:F14) | G15: =SUM(G5:G14)/5 | H15: =SUM(H5:H13)

Sheet Co7
B4: Observe Date/Class
B5: 1 | C5: Lesson planning and preparation | D5: The teacher is following a clear and well-structured lesson plan. | E5: The teacher tailors the lesson to meet the students’ needs and proficiency level. | F5: Appropriate and varied materials are prepared and used effectively | G5: Average Observe | H5: Comments
G6: =AVERAGE(D6,E6,F6)
B7: 2 | C7: Classroom management | D7: The classroom environment is conductive to learning. | E7: Students are actively engaged and participating throughout the lesson. | F7: The teacher manages class time, transitions and activities effectively. | G7: Average Observe | H7: Comments:
G8: =AVERAGE(D8,E8,F8)
B9: 3 | C9: Instructional delivery | D9: The teacher provides clear and differentiated instructions and explanations. | E9: The teacher uses the appropriate language level for students. | F9: The teacher encourages interaction and communication among students. | G9: Average Observe | H9: Comments
G10: =AVERAGE(D10,E10,F10)
B11: 4 | C11: Assessment and feedback | D11: The teacher monitors student progress during the lesson. | E11: The teacher provides timely and constructive feedback. | F11: The teacher adjusts teaching based on students’ understanding and feedback | G11: Average Observe | H11: Comments
G12: =AVERAGE(D12,E12,F12)
B13: 5 | C13: Language use | D13: The teacher integrates grammar, vocabulary and pronunciation effectively. | E13: The teacher provides opportunities for students to practice and use English. | F13: The teacher is a proficient model of language. | G13: Average Observe | H13: Comments
G14: =AVERAGE(D14,E14,F14)
B15: Sum | D15: =SUM(D5:D14) | E15: =SUM(E5:E14) | F15: =SUM(F5:F14) | G15: =SUM(G5:G14)/5 | H15: =SUM(H5:H13)

Sheet Co8
B4: Observe Date/Class
B5: 1 | C5: Lesson planning and preparation | D5: The teacher is following a clear and well-structured lesson plan. | E5: The teacher tailors the lesson to meet the students’ needs and proficiency level. | F5: Appropriate and varied materials are prepared and used effectively | G5: Average Observe | H5: Comments
G6: =AVERAGE(D6,E6,F6)
B7: 2 | C7: Classroom management | D7: The classroom environment is conductive to learning. | E7: Students are actively engaged and participating throughout the lesson. | F7: The teacher manages class time, transitions and activities effectively. | G7: Average Observe | H7: Comments:
G8: =AVERAGE(D8,E8,F8)
B9: 3 | C9: Instructional delivery | D9: The teacher provides clear and differentiated instructions and explanations. | E9: The teacher uses the appropriate language level for students. | F9: The teacher encourages interaction and communication among students. | G9: Average Observe | H9: Comments
G10: =AVERAGE(D10,E10,F10)
B11: 4 | C11: Assessment and feedback | D11: The teacher monitors student progress during the lesson. | E11: The teacher provides timely and constructive feedback. | F11: The teacher adjusts teaching based on students’ understanding and feedback | G11: Average Observe | H11: Comments
G12: =AVERAGE(D12,E12,F12)
B13: 5 | C13: Language use | D13: The teacher integrates grammar, vocabulary and pronunciation effectively. | E13: The teacher provides opportunities for students to practice and use English. | F13: The teacher is a proficient model of language. | G13: Average Observe | H13: Comments
G14: =AVERAGE(D14,E14,F14)
B15: Sum | D15: =SUM(D5:D14) | E15: =SUM(E5:E14) | F15: =SUM(F5:F14) | G15: =SUM(G5:G14)/5 | H15: =SUM(H5:H13)

Sheet Co9
B4: Observe Date/Class
B5: 1 | C5: Lesson planning and preparation | D5: The teacher is following a clear and well-structured lesson plan. | E5: The teacher tailors the lesson to meet the students’ needs and proficiency level. | F5: Appropriate and varied materials are prepared and used effectively | G5: Average Observe | H5: Comments
G6: =AVERAGE(D6,E6,F6)
B7: 2 | C7: Classroom management | D7: The classroom environment is conductive to learning. | E7: Students are actively engaged and participating throughout the lesson. | F7: The teacher manages class time, transitions and activities effectively. | G7: Average Observe | H7: Comments:
G8: =AVERAGE(D8,E8,F8)
B9: 3 | C9: Instructional delivery | D9: The teacher provides clear and differentiated instructions and explanations. | E9: The teacher uses the appropriate language level for students. | F9: The teacher encourages interaction and communication among students. | G9: Average Observe | H9: Comments
G10: =AVERAGE(D10,E10,F10)
B11: 4 | C11: Assessment and feedback | D11: The teacher monitors student progress during the lesson. | E11: The teacher provides timely and constructive feedback. | F11: The teacher adjusts teaching based on students’ understanding and feedback | G11: Average Observe | H11: Comments
G12: =AVERAGE(D12,E12,F12)
B13: 5 | C13: Language use | D13: The teacher integrates grammar, vocabulary and pronunciation effectively. | E13: The teacher provides opportunities for students to practice and use English. | F13: The teacher is a proficient model of language. | G13: Average Observe | H13: Comments
G14: =AVERAGE(D14,E14,F14)
B15: Sum | D15: =SUM(D5:D14) | E15: =SUM(E5:E14) | F15: =SUM(F5:F14) | G15: =SUM(G5:G14)/5 | H15: =SUM(H5:H13)

Sheet results
B3: Teacher | C3: =blank!B3 | H3: قدرت جذب
B4: row | C4: class | D4: Observe | E4: مجازی | F4: حضوری | G4: حضوری | I4: 1403 | J4: 1404
B5: 1 | C5: ='Co Zero'!H4 | D5: ='Co Zero'!G15 | G5: ='Co Zero'!D4 | H5: زمستان به بهار
B6: 2 | C6: ='co 1'!H4 | D6: ='co 1'!G15 | G6: ='co 1'!D4 | H6: بهار به تابستان
B7: 3 | C7: ='Co2'!H4 | D7: ='Co2'!G15 | G7: ='Co2'!D4 | H7: تابستان به پاییز
B8: 4 | C8: ='Co3'!H4 | D8: ='Co3'!G15 | G8: ='Co3'!D4 | H8: پاییز به زمستان
B9: 5 | C9: ='Co4'!H4 | D9: ='Co4'!G15 | G9: ='Co4'!D4
B10: 6 | C10: ='Co5'!H4 | D10: ='Co5'!G15 | G10: ='Co5'!D4
B11: 7 | C11: ='Co6'!H4 | D11: ='Co6'!G15 | G11: ='Co6'!D4
B12: 8 | C12: ='Co7'!H4 | D12: ='Co7'!G15 | G12: ='Co7'!D4
B13: 9 | C13: ='Co8'!H4 | D13: ='Co8'!G15 | G13: ='Co8'!D4
B14: 10 | C14: ='Co9'!H4 | D14: ='Co9'!G15 | G14: ='Co9'!D4
C21: Pre Kc/Kc
C22: Pre-A1 | D22: Pre-KC / KC2d | E22: 1
C23: A1 | D23: KC3a/KC3d | E23: 2
C24: A1+ | D24: KC4a/KC4c | E24: 3
C37: CES
C38: A1 | D38: StA/C | E38: 1
C39: A1+ | D39: CES1/2 | E39: 2
C40: A2 | D40: CES3 | E40: 3
C41: A2+ | D41: CES4/5 | E41: 4
C42: B1 | D42: CES6 | E42: 4
C58: MIC
C59: A1 | D59: Basics | E59: 1
C60: A1+ | D60: SE1/2 | E60: 2
C61: A2 | D61: SE3/4 | E61: 3
C62: A2+ | D62: SP1/4 | E62: 4
C63: B1 | D63: SI1/2 | E63: 5
C64: B1+ | D64: SI3/4 | E64: 6
C65: B2 | D65: SU1/2 | E65: 7
C66: B2+ | D66: SU3/4 | E66: 8
C78: Adults (CO-CPE)
C79: A1 | D79: COZ/2 | E79: 1
C80: A1+ | D80: CO3/4 | E80: 2
C81: A2 | D81: CO4+/CO5 | E81: 3
C82: A2+ | D82: CO6/6+ | E82: 4
C83: B1 | D83: CO7/8 | E83: 5
C84: B1+ | D84: CO9 | E84: 6
C85: B2 | D85: COMP1-2/FCE1-2 | E85: 7
C86: B2+ | D86: COMP3-4/FCE3-4 | E86: 8
...
